2020-08-04 10:00:40.346 | WARNING  | common.base_api:__init__:25 - 数据库连接时发生异常:
2020-08-04 10:00:40.352 | ERROR    | test_CJXM:<module>:8 - An error has been caught in function '<module>', process 'MainProcess' (16276), thread 'MainThread' (15476):
Traceback (most recent call last):

  File "run.py", line 12, in <module>
    one_test_case = unittest.defaultTestLoader.discover(case_path, pattern='test*.py')
                    │        │                 │        └ 'C:\\Users\\小米笔记本\\Desktop\\全篇\\testcase'
                    │        │                 └ <function TestLoader.discover at 0x0000024963A47730>
                    │        └ <unittest.loader.TestLoader object at 0x0000024963A41828>
                    └ <module 'unittest' from 'D:\\办公软件\\python\\lib\\unittest\\__init__.py'>

  File "D:\办公软件\python\lib\unittest\loader.py", line 347, in discover
    tests = list(self._find_tests(start_dir, pattern))
                 │    │           │          └ 'test*.py'
                 │    │           └ 'C:\\Users\\小米笔记本\\Desktop\\全篇\\testcase'
                 │    └ <function TestLoader._find_tests at 0x0000024963A479D8>
                 └ <unittest.loader.TestLoader object at 0x0000024963A41828>

  File "D:\办公软件\python\lib\unittest\loader.py", line 404, in _find_tests
    full_path, pattern, namespace)
    │          │        └ False
    │          └ 'test*.py'
    └ 'C:\\Users\\小米笔记本\\Desktop\\全篇\\testcase\\test_CJXM.py'

  File "D:\办公软件\python\lib\unittest\loader.py", line 434, in _find_test_path
    module = self._get_module_from_name(name)
             │    │                     └ 'test_CJXM'
             │    └ <function TestLoader._get_module_from_name at 0x0000024963A478C8>
             └ <unittest.loader.TestLoader object at 0x0000024963A41828>

  File "D:\办公软件\python\lib\unittest\loader.py", line 375, in _get_module_from_name
    __import__(name)
               └ 'test_CJXM'

  File "<frozen importlib._bootstrap>", line 983, in _find_and_load
  File "<frozen importlib._bootstrap>", line 967, in _find_and_load_unlocked
  File "<frozen importlib._bootstrap>", line 677, in _load_unlocked
  File "<frozen importlib._bootstrap_external>", line 728, in exec_module
  File "<frozen importlib._bootstrap>", line 219, in _call_with_frames_removed

> File "C:\Users\小米笔记本\Desktop\全篇\testcase\test_CJXM.py", line 8, in <module>
    sql = SQL().select_all(table_name='testcase_cjxm')
          └ <class 'common.base_api.SQL'>

  File "C:\Users\小米笔记本\Desktop\全篇\common\base_api.py", line 57, in select_all
    cursors = self.creat_connect()
              │    └ <function SQL.creat_connect at 0x0000024964ACFA60>
              └ <common.base_api.SQL object at 0x00000249641CCE80>

  File "C:\Users\小米笔记本\Desktop\全篇\common\base_api.py", line 31, in creat_connect
    self.cursor = self.connection.cursor()
    │    │        └ <common.base_api.SQL object at 0x00000249641CCE80>
    │    └ None
    └ <common.base_api.SQL object at 0x00000249641CCE80>

AttributeError: 'SQL' object has no attribute 'connection'
2020-08-04 10:00:44.463 | WARNING  | common.base_api:__init__:25 - 数据库连接时发生异常:(2003, "Can't connect to MySQL server on 'localhost' ([WinError 10061] 由于目标计算机积极拒绝，无法连接。)")
2020-08-04 10:00:44.470 | ERROR    | test_NDXS:<module>:4 - An error has been caught in function '<module>', process 'MainProcess' (16276), thread 'MainThread' (15476):
Traceback (most recent call last):

  File "run.py", line 12, in <module>
    one_test_case = unittest.defaultTestLoader.discover(case_path, pattern='test*.py')
                    │        │                 │        └ 'C:\\Users\\小米笔记本\\Desktop\\全篇\\testcase'
                    │        │                 └ <function TestLoader.discover at 0x0000024963A47730>
                    │        └ <unittest.loader.TestLoader object at 0x0000024963A41828>
                    └ <module 'unittest' from 'D:\\办公软件\\python\\lib\\unittest\\__init__.py'>

  File "D:\办公软件\python\lib\unittest\loader.py", line 347, in discover
    tests = list(self._find_tests(start_dir, pattern))
                 │    │           │          └ 'test*.py'
                 │    │           └ 'C:\\Users\\小米笔记本\\Desktop\\全篇\\testcase'
                 │    └ <function TestLoader._find_tests at 0x0000024963A479D8>
                 └ <unittest.loader.TestLoader object at 0x0000024963A41828>

  File "D:\办公软件\python\lib\unittest\loader.py", line 404, in _find_tests
    full_path, pattern, namespace)
    │          │        └ False
    │          └ 'test*.py'
    └ 'C:\\Users\\小米笔记本\\Desktop\\全篇\\testcase\\test_NDXS.py'

  File "D:\办公软件\python\lib\unittest\loader.py", line 434, in _find_test_path
    module = self._get_module_from_name(name)
             │    │                     └ 'test_NDXS'
             │    └ <function TestLoader._get_module_from_name at 0x0000024963A478C8>
             └ <unittest.loader.TestLoader object at 0x0000024963A41828>

  File "D:\办公软件\python\lib\unittest\loader.py", line 375, in _get_module_from_name
    __import__(name)
               └ 'test_NDXS'

  File "<frozen importlib._bootstrap>", line 983, in _find_and_load
  File "<frozen importlib._bootstrap>", line 967, in _find_and_load_unlocked
  File "<frozen importlib._bootstrap>", line 677, in _load_unlocked
  File "<frozen importlib._bootstrap_external>", line 728, in exec_module
  File "<frozen importlib._bootstrap>", line 219, in _call_with_frames_removed

> File "C:\Users\小米笔记本\Desktop\全篇\testcase\test_NDXS.py", line 4, in <module>
    sql = SQL().select_all(table_name='testcase_ndxs')
          └ <class 'common.base_api.SQL'>

  File "C:\Users\小米笔记本\Desktop\全篇\common\base_api.py", line 57, in select_all
    cursors = self.creat_connect()
              │    └ <function SQL.creat_connect at 0x0000024964ACFA60>
              └ <common.base_api.SQL object at 0x0000024964AD6898>

  File "C:\Users\小米笔记本\Desktop\全篇\common\base_api.py", line 31, in creat_connect
    self.cursor = self.connection.cursor()
    │    │        └ <common.base_api.SQL object at 0x0000024964AD6898>
    │    └ None
    └ <common.base_api.SQL object at 0x0000024964AD6898>

AttributeError: 'SQL' object has no attribute 'connection'
